Workbook

Sheet assoi
A3: Счет АССОИ | B3: Счет КИС | C3: Код продукции(статьи) АССОИ | D3: Имя продукции(статьи) АССОИ | E3: Продукция КИС | F3: Код контрагента АССОИ | G3: Контрагент АССОИ | H3: Код Контрагента КИС | I3: Контрагент КИС | J3: Валюта | K3: Ед.Изм | L3: Период | M3: Год | N3: Колонка | O3: Значение (2 373 601) | P3: По модулю | Q3: coef | R3: Комментарий
A6: BA090_08 | B6: 90.1010000 | C6: m15031600 | D6: Катоды медные | E6: 89688 | F6: 2280 | G6: ПАО "КУЗОЦМ" | H6: 1258 | I6: КУЗОЦМ АО | J6: RUB*1000 | K6: NONE | L6: 111 | M6: 2022 | N6: SLSSFIX | O6: 70067 | P6: false | R6: 70066585,68999999800000 RUB*1000 > RUB*1000;
A7: BA090_08 | B7: 90.1010000 | C7: m15032100 | D7: Слитки медные | E7: 651433 | F7: 12375 | G7: СТМ ООО | H7: 208535 | I7: СТМ ООО | J7: RUB*1000 | K7: NONE | L7: 111 | M7: 2022 | N7: SLSSFIX | O7: 3096 | P7: false | R7: 3096018,79999999980000 RUB*1000 > RUB*1000;
A8: BA090_08 | B8: 90.1010000 | C8: m15032100 | D8: Слитки медные | E8: 695002 | F8: 9950 | G8: ООО "ЛИСТ СПб" | H8: 69920 | I8: ЛИСТ СПБ ООО | J8: RUB*1000 | K8: NONE | L8: 111 | M8: 2022 | N8: SLSSFIX | O8: 543 | P8: false | R8: 542974,15000000002000 RUB*1000 > RUB*1000;
A9: BA090_08 | B9: 90.1010000 | C9: m15041130 | D9: Прокат медный | E9: 650280, 650281, 650282, 650622, 650623, 663965 | F9: 10722 | G9: ООО "НПЦ Металлург" | H9: 66325 | I9: НПЦ МЕТАЛЛУРГ ООО | J9: RUB*1000 | K9: NONE | L9: 111 | M9: 2022 | N9: SLSSFIX | O9: 11807 | P9: false | R9: 6168588,79999999980000 + 616319,76000000001000 + 1265600,00000000000000 + 1231494,39999999990000 + 1232729,60000000010000 + 1292177,60000000010000 RUB*1000 > RUB*1000;
A10: BA090_08 | B10: 90.1010000 | C10: m15041130 | D10: Прокат медный | E10: 651017, 651214, 651221, 652055, 652143, 652158, 652159, 652164, 652167, 652335, 652347, 652350, 652356, 652369, 653190, 653191, 653195, 653230, 653343, 653350, 658575, 670179 | F10: 10723 | G10: ООО "АЛЬМЕТ" | H10: 126128 | I10: АЛЬМЕТ ООО | J10: RUB*1000 | K10: NONE | L10: 111 | M10: 2022 | N10: SLSSFIX | O10: 5299 | P10: false | R10: 191394,00000000000000 + 242625,60000000001000 + 295214,40000000002000 + 232835,20000000001000 + 194544,00000000000000 + 413613,59999999998000 + 303959,26000000001000 + 184710,39999999999000 + 177868,79999999999000 + 192128,39999999999000 + 218661,84000000000000 + 167865,84000000000000 + 277286,40000000002000 + 114918,48000000000000 + 181670,39999999999000 + 179280,00000000000000 + 180475,20000000001000 + 364834,79999999999000 + 422783,46000000002000 + 177366,29999999999000 + 392836,00000000000000 + 192073,60000000001000 RUB*1000 > RUB*1000;
A11: BA090_08 | B11: 90.1010000 | C11: m15041130 | D11: Прокат медный | E11: 659579, 659580, 659582, 659583, 660033, 660039, 660043, 660067 | F11: 10837 | G11: ООО "СВЕРДЛОВЭЛЕКТРО" | H11: 20784 | I11: СВЕРДЛОВЭЛЕКТРО ООО | J11: RUB*1000 | K11: NONE | L11: 111 | M11: 2022 | N11: SLSSFIX | O11: 10133 | P11: false | R11: 2282269,99000000020000 + 1088811,93999999990000 + 1384662,36000000010000 + 2291278,24000000020000 + 1104642,00000000000000 + 396272,34999999998000 + 520008,00000000000000 + 1065463,20000000000000 RUB*1000 > RUB*1000;
A12: BA090_08 | B12: 90.1010000 | C12: m15041130 | D12: Прокат медный | E12: 651299, 653277 | F12: 10842 | G12: ООО "СПИРАЛЬ" | H12: 124818 | I12: СПИРАЛЬ ООО | J12: RUB*1000 | K12: NONE | L12: 111 | M12: 2022 | N12: SLSSFIX | O12: 5982 | P12: false | R12: 1228702,80000000000000 + 4752990,91999999990000 RUB*1000 > RUB*1000;
A13: BA090_08 | B13: 90.1010000 | C13: m15041130 | D13: Прокат медный | E13: 651495 | F13: 10845 | G13: ООО "Уромгаз-Ирбит" | H13: 125683 | I13: УРОМГАЗ-ИРБИТ ООО | J13: RUB*1000 | K13: NONE | L13: 111 | M13: 2022 | N13: SLSSFIX | O13: 1453 | P13: false | R13: 1452897,60000000010000 RUB*1000 > RUB*1000;
A14: BA090_08 | B14: 90.1010000 | C14: m15041130 | D14: Прокат медный | E14: 653795 | F14: 10848 | G14: АО "ПОЗИС" | H14: 135819 | I14: ПОЗИС АО | J14: RUB*1000 | K14: NONE | L14: 111 | M14: 2022 | N14: SLSSFIX | O14: 1257 | P14: false | R14: 1257186,08000000010000 RUB*1000 > RUB*1000;
A15: BA090_08 | B15: 90.1010000 | C15: m15041130 | D15: Прокат медный | E15: 650648, 650649, 650652, 650654, 650655 | F15: 10856 | G15: АО "ДКС" | H15: 205357 | I15: ДКС АО | J15: RUB*1000 | K15: NONE | L15: 111 | M15: 2022 | N15: SLSSFIX | O15: 6918 | P15: false | R15: 213344,00000000000000 + 348582,40000000002000 + 1524736,39999999990000 + 1802214,39999999990000 + 3029484,79999999980000 RUB*1000 > RUB*1000;
A16: BA090_08 | B16: 90.1010000 | C16: m15041130 | D16: Прокат медный | E16: 651618, 652821, 652830, 652840, 652841, 652862, 655511, 655528, 655543, 656741, 656798, 656824, 656826, 656834, 656841, 657899, 657919, 658568, 658570, 658574, 658577, 659542, 659544, 659995, 660328, 660332 | F16: 10857 | G16: НПК МЕТАПРОМ ООО | H16: 208503 | I16: НПК МЕТАПРОМ ООО | J16: RUB*1000 | K16: NONE | L16: 111 | M16: 2022 | N16: SLSSFIX | O16: 22795 | P16: false | R16: 281799,29999999999000 + 941978,43999999994000 + 1155304,76000000000000 + 762233,43999999994000 + 592992,00000000000000 + 574248,00000000000000 + 114736,00000000000000 + 1016720,00000000000000 + 1545528,00000000000000 + 225876,60000000001000 + 135710,39999999999000 + 461959,67999999999000 + 809172,19999999995000 + 1421405,96000000000000 + 789493,12000000000000 + 1077014,36000000010000 + 3405461,39999999990000 + 1872873,20000000000000 + 179864,35999999999000 + 501006,67999999999000 + 937418,35999999999000 + 492219,29999999999000 + 1333501,70000000000000 + 1698140,08000000010000 + 342057,59999999998000 + 126454,16000000000000 RUB*1000 > RUB*1000;
A17: BA090_08 | B17: 90.1010000 | C17: m15041130 | D17: Прокат медный | E17: 652454, 652459, 653909, 654056, 707800 | F17: 10858 | G17: МЕЛЬХИОР ООО | H17: 208504 | I17: МЕЛЬХИОР ООО | J17: RUB*1000 | K17: NONE | L17: 111 | M17: 2022 | N17: SLSSFIX | O17: 17010 | P17: false | R17: 294814,96000000002000 + 765592,12000000000000 + 359668,40000000002000 + 2029020,00000000000000 + 13561246,80000000100000 RUB*1000 > RUB*1000;
A18: BA090_08 | B18: 90.1010000 | C18: m15041130 | D18: Прокат медный | E18: 650623, 652596 | F18: 10860 | G18: АО "СКБ СИБЭЛЕКТРОТЕРМ" | H18: 208553 | I18: СКБ СИБЭЛЕКТРОТЕРМ АО | J18: RUB*1000 | K18: NONE | L18: 111 | M18: 2022 | N18: SLSSFIX | O18: 3409 | P18: false | R18: 2640808,79999999980000 + 768592,80000000005000 RUB*1000 > RUB*1000;
A19: BA090_08 | B19: 90.1010000 | C19: m15041130 | D19: Прокат медный | E19: 650953, 681414 | F19: 10862 | G19: АО "АМЕТИСТ-СТАН" | H19: 208597 | I19: АМЕТИСТ-СТАН АО | J19: RUB*1000 | K19: NONE | L19: 111 | M19: 2022 | N19: SLSSFIX | O19: 4192 | P19: false | R19: 174768,00000000000000 + 4016942,18000000020000 RUB*1000 > RUB*1000;
A20: BA090_08 | B20: 90.1010000 | C20: m15041130 | D20: Прокат медный | E20: 653277 | F20: 10863 | G20: ООО "СПИРАЛЬПЛЮС" | H20: 208609 | I20: СПИРАЛЬПЛЮС ООО | J20: RUB*1000 | K20: NONE | L20: 111 | M20: 2022 | N20: SLSSFIX | O20: 2401 | P20: false | R20: 2401331,39999999990000 RUB*1000 > RUB*1000;
A21: BA090_08 | B21: 90.1010000 | C21: m15041130 | D21: Прокат медный | E21: 658887, 659366, 659781, 660276, 698976 | F21: 10866 | G21: ООО "ТДР" | H21: 208686 | I21: ТДР ООО | J21: RUB*1000 | K21: NONE | L21: 111 | M21: 2022 | N21: SLSSFIX | O21: 7617 | P21: false | R21: 4389469,00000000000000 + 1102155,20000000000000 + 300868,59999999998000 + 1257840,80000000000000 + 566522,59999999998000 RUB*1000 > RUB*1000;
A22: BA090_08 | B22: 90.1010000 | C22: m15041130 | D22: Прокат медный | E22: 651540 | F22: 10875 | G22: АО "ТЭМЗ" | H22: 5028 | I22: ТЭМЗ АО | J22: RUB*1000 | K22: NONE | L22: 111 | M22: 2022 | N22: SLSSFIX | O22: 104 | P22: false | R22: 103542,39999999999000 RUB*1000 > RUB*1000;
A23: BA090_08 | B23: 90.1010000 | C23: m15041130 | D23: Прокат медный | E23: 657944 | F23: 12340 | G23: ООО "Сплав М" | H23: 72909 | I23: СПЛАВ М ООО | J23: RUB*1000 | K23: NONE | L23: 111 | M23: 2022 | N23: SLSSFIX | O23: 2036 | P23: false | R23: 2035516,80000000000000 RUB*1000 > RUB*1000;
A24: BA090_08 | B24: 90.1010000 | C24: m15041130 | D24: Прокат медный | E24: 650280 | F24: 12344 | G24: ООО "Маркетинг-Бюро. Металл" | H24: 123157 | I24: МАРКЕТИНГ-БЮРО.МЕТАЛЛ ООО | J24: RUB*1000 | K24: NONE | L24: 111 | M24: 2022 | N24: SLSSFIX | O24: 190 | P24: false | R24: 190296,12000000000000 RUB*1000 > RUB*1000;
A25: BA090_08 | B25: 90.1010000 | C25: m15041130 | D25: Прокат медный | E25: 654011, 655463, 655467 | F25: 12348 | G25: ООО "КамаМеталлКомплект" | H25: 124717 | I25: КАМАМЕТАЛЛКОМПЛЕКТ ООО | J25: RUB*1000 | K25: NONE | L25: 111 | M25: 2022 | N25: SLSSFIX | O25: 1982 | P25: false | R25: 1004631,60000000000000 + 753654,00000000000000 + 223572,00000000000000 RUB*1000 > RUB*1000;
A26: BA090_08 | B26: 90.1010000 | C26: m15041130 | D26: Прокат медный | E26: 701200 | F26: 12349 | G26: ООО "СИМЕНС ЭНЕРГЕТИКА ТРАНСФОРМАТОРЫ" | H26: 125023 | I26: ВОРОНЕЖСКИЙ ТРАНСФОРМАТОР ООО | J26: RUB*1000 | K26: NONE | L26: 111 | M26: 2022 | N26: SLSSFIX | O26: 415 | P26: false | R26: 414752,40000000002000 RUB*1000 > RUB*1000;
A27: BA090_08 | B27: 90.1010000 | C27: m15041130 | D27: Прокат медный | E27: 650390, 709580, 709581 | F27: 12351 | G27: ООО "СМЦ Маркетинг-Бюро" | H27: 125117 | I27: СМЦ МАРКЕТИНГ-БЮРО ООО | J27: RUB*1000 | K27: NONE | L27: 111 | M27: 2022 | N27: SLSSFIX | O27: 673 | P27: false | R27: 298845,79999999999000 + 182603,51999999999000 + 191480,07999999999000 RUB*1000 > RUB*1000;
A28: BA090_08 | B28: 90.1010000 | C28: m15041130 | D28: Прокат медный | E28: 658931 | F28: 12352 | G28: ООО "ПЛАСТИКПАК" | H28: 125440 | I28: ПЛАСТИКПАК ООО | J28: RUB*1000 | K28: NONE | L28: 111 | M28: 2022 | N28: SLSSFIX | O28: 172 | P28: false | R28: 172221,60000000001000 RUB*1000 > RUB*1000;
A29: BA090_08 | B29: 90.1010000 | C29: m15041130 | D29: Прокат медный | E29: 652742 | F29: 12353 | G29: ООО "Кабельная арматура" | H29: 125835 | I29: КАБЕЛЬНАЯ АРМАТУРА ООО | J29: RUB*1000 | K29: NONE | L29: 111 | M29: 2022 | N29: SLSSFIX | O29: 311 | P29: false | R29: 311304,00000000000000 RUB*1000 > RUB*1000;
A30: BA090_08 | B30: 90.1010000 | C30: m15041130 | D30: Прокат медный | E30: 651781, 653994, 654046, 654049, 656712, 656714, 686969, 688157, 689570, 690141, 690142, 691750, 691753, 693046, 693047, 693197, 693198, 694646, 694647, 695198, 696928, 700560, 705218 | F30: 12354 | G30: ООО "ДПА" | H30: 125847 | I30: ДПА ООО | J30: RUB*1000 | K30: NONE | L30: 111 | M30: 2022 | N30: SLSSFIX | O30: 10550 | P30: false | R30: 657262,90000000002000 + 832611,15000000002000 + 152237,79999999999000 + 621336,09999999998000 + 368763,59999999998000 + 185731,00000000000000 + 392801,79999999999000 + 670945,56000000006000 + 532117,80000000005000 + 314976,40000000002000 + 703617,59999999998000 + 983129,17000000004000 + 295221,59999999998000 + 777096,69999999995000 + 431033,64000000001000 + 337632,75000000000000 + 378693,00000000000000 + 308096,03999999998000 + 190329,60000000001000 + 275780,70000000001000 + 362589,50000000000000 + 301553,46000000002000 + 476168,09999999998000 RUB*1000 > RUB*1000;
A31: BA090_08 | B31: 90.1010000 | C31: m15041130 | D31: Прокат медный | E31: 653414 | F31: 12364 | G31: ООО "МИКОМЕТ" | H31: 193632 | I31: МИКОМЕТ ООО | J31: RUB*1000 | K31: NONE | L31: 111 | M31: 2022 | N31: SLSSFIX | O31: 1294 | P31: false | R31: 1293619,50000000000000 RUB*1000 > RUB*1000;
A32: BA090_08 | B32: 90.1010000 | C32: m15041130 | D32: Прокат медный | E32: 650168, 651250 | F32: 12369 | G32: ООО "МПК ИННОМЕТ" | H32: 195025 | I32: МПК ИННОМЕТ ООО | J32: RUB*1000 | K32: NONE | L32: 111 | M32: 2022 | N32: SLSSFIX | O32: 3232 | P32: false | R32: 2727743,60000000010000 + 504665,70000000001000 RUB*1000 > RUB*1000;
A33: BA090_08 | B33: 90.1010000 | C33: m15041130 | D33: Прокат медный | E33: 651278, 653230 | F33: 12370 | G33: АО "ЭЛЕКТРУМ АВ" | H33: 195052 | I33: ЭЛЕКТРУМ АВ АО | J33: RUB*1000 | K33: NONE | L33: 111 | M33: 2022 | N33: SLSSFIX | O33: 504 | P33: false | R33: 236232,00000000000000 + 267729,59999999998000 RUB*1000 > RUB*1000;
A34: BA090_08 | B34: 90.1010000 | C34: m15041130 | D34: Прокат медный | E34: 651640, 652748, 654758, 654976, 656341, 656345, 656350, 656366, 656372, 656393, 656396, 657860, 658322, 658882, 658919, 658938, 659373, 659374, 659376, 659419, 659774, 659778, 659782, 659788, 659790, 673546, 673554 | F34: 12371 | G34: ООО "ВЕНДОР-Проф" | H34: 195097 | I34: ВЕНДОР-ПРОФ ООО | J34: RUB*1000 | K34: NONE | L34: 111 | M34: 2022 | N34: SLSSFIX | O34: 6824 | P34: false | R34: 744604,00000000000000 + 341628,00000000000000 + 718536,96999999997000 + 219016,69000000000000 + 211297,17000000001000 + 1704,55999999999990 + 588026,90000000002000 + 46749,26000000000200 + 159617,20999999999000 + 158318,39000000001000 + 230609,60999999999000 + 712910,06000000006000 + 7892,96000000000000 + 715598,93000000005000 + 33701,19000000000200 + 252000,00000000000000 + 1097512,00000000000000 + 8442,39999999999960 + 135302,20000000001000 + 102900,72000000000000 + 57583,88999999999900 + 9461,70000000000070 + 15679,50000000000000 + 29764,86999999999900 + 12287,25000000000000 + 86039,89999999999400 + 126624,89999999999000 RUB*1000 > RUB*1000;
A35: BA090_08 | B35: 90.1010000 | C35: m15041130 | D35: Прокат медный | E35: 650289, 651214, 653216 | F35: 12386 | G35: ТОРГОВО-ПРОИЗВОДСТВЕННОЕ УНИТАРНОЕ ПРЕДПРИЯТИЕ "КОЛОРПРОКАТ" | H35: 208941 | I35: КОЛОРПРОКАТ ТП УП | J35: RUB*1000 | K35: NONE | L35: 111 | M35: 2022 | N35: SLSSFIX | O35: 649 | P35: false | R35: 190382,39999999999000 + 288100,00000000000000 + 170555,20000000001000 RUB*1000 > RUB*1000;
A36: BA090_08 | B36: 90.1010000 | C36: m15041130 | D36: Прокат медный | E36: 651331, 651336, 651341, 651345, 653301, 691093 | F36: 12387 | G36: ОАО "МИНСКИЙ ЭЛЕКТРОТЕХНИЧЕСКИЙ ЗАВОД ИМЕНИ В.И. КОЗЛОВА" | H36: 208986 | I36: МЭТЗ ИМ. В.И.КОЗЛОВА ОАО | J36: RUB*1000 | K36: NONE | L36: 111 | M36: 2022 | N36: SLSSFIX | O36: 7227 | P36: false | R36: 179139,20000000001000 + 615851,52000000002000 + 3651655,75999999980000 + 1883685,00000000000000 + 594306,40000000002000 + 302600,00000000000000 RUB*1000 > RUB*1000;
A37: BA090_08 | B37: 90.1010000 | C37: m15041130 | D37: Прокат медный | E37: 650990 | F37: 12396 | G37: ООО "ФОНД-МЕТАЛЛ" | H37: 115136 | I37: ФОНД-МЕТАЛЛ ООО | J37: RUB*1000 | K37: NONE | L37: 111 | M37: 2022 | N37: SLSSFIX | O37: 649 | P37: false | R37: 648924,00000000000000 RUB*1000 > RUB*1000;
A38: BA090_08 | B38: 90.1010000 | C38: m15041130 | D38: Прокат медный | E38: 695691 | F38: 12398 | G38: ООО ТК "АКТИМИСТА" | H38: 122083 | I38: ТК АКТИМИСТА ООО | J38: RUB*1000 | K38: NONE | L38: 111 | M38: 2022 | N38: SLSSFIX | O38: 233 | P38: false | R38: 232814,39999999999000 RUB*1000 > RUB*1000;
A39: BA090_08 | B39: 90.1010000 | C39: m15041130 | D39: Прокат медный | E39: 653385, 654714 | F39: 12399 | G39: ООО "ЧЕДЕМ" | H39: 122927 | I39: ЧЕДЕМ ООО | J39: RUB*1000 | K39: NONE | L39: 111 | M39: 2022 | N39: SLSSFIX | O39: 3058 | P39: false | R39: 2025193,41999999990000 + 1032854,28000000000000 RUB*1000 > RUB*1000;
A40: BA090_08 | B40: 90.1010000 | C40: m15041130 | D40: Прокат медный | E40: 652747, 652748, 653728, 655456, 655457, 659374, 659774, 659778, 659782, 660270 | F40: 12408 | G40: ООО "КОМПАНИЯ ЭКОПРОЕКТ" | H40: 163963 | I40: КОМПАНИЯ ЭКОПРОЕКТ ООО | J40: RUB*1000 | K40: NONE | L40: 111 | M40: 2022 | N40: SLSSFIX | O40: 962 | P40: false | R40: 229068,00000000000000 + 226886,39999999999000 + 31047,00000000000000 + 188344,79999999999000 + 218160,00000000000000 + 8977,60000000000040 + 20565,66999999999800 + 9461,70000000000070 + 15679,50000000000000 + 13418,40000000000000 RUB*1000 > RUB*1000;
A41: BA090_08 | B41: 90.1010000 | C41: m15041130 | D41: Прокат медный | E41: 650303 | F41: 12414 | G41: ООО "ЭМС" | H41: 194923 | I41: ЭМС ООО | J41: RUB*1000 | K41: NONE | L41: 111 | M41: 2022 | N41: SLSSFIX | O41: 2208 | P41: false | R41: 2208450,39999999990000 RUB*1000 > RUB*1000;
A42: BA090_08 | B42: 90.1010000 | C42: m15041130 | D42: Прокат медный | E42: 652766 | F42: 12418 | G42: ООО "Завод КОНОРД" | H42: 195092 | I42: ЗАВОД КОНОРД ООО | J42: RUB*1000 | K42: NONE | L42: 111 | M42: 2022 | N42: SLSSFIX | O42: 1871 | P42: false | R42: 1870616,45000000000000 RUB*1000 > RUB*1000;
A43: BA090_08 | B43: 90.1010000 | C43: m15041130 | D43: Прокат медный | E43: 673554 | F43: 12423 | G43: РПХ ООО | H43: 208524 | I43: РПХ ООО | J43: RUB*1000 | K43: NONE | L43: 111 | M43: 2022 | N43: SLSSFIX | O43: 17 | P43: false | R43: 16823,66999999999800 RUB*1000 > RUB*1000;
A44: BA090_08 | B44: 90.1010000 | C44: m15041130 | D44: Прокат медный | E44: 652683, 652705, 654947, 654948, 654949 | F44: 12426 | G44: ООО "СТРИМ МЕХАНИК" | H44: 208667 | I44: СТРИМ МЕХАНИК ООО | J44: RUB*1000 | K44: NONE | L44: 111 | M44: 2022 | N44: SLSSFIX | O44: 7509 | P44: false | R44: 1082832,00000000000000 + 4335667,00000000000000 + 460620,15999999997000 + 745972,80000000005000 + 883536,00000000000000 RUB*1000 > RUB*1000;
...

Sheet sap_11
A1: Код_sap | B1: Код_assoi | C1: Строка_АССОИ | D1: ТекстКлиент | E1: Группа материалов | F1: Материал | G1: ТекстГруппа материалов | H1: ТекстМатериал | I1: Код ОКВЭД | J1: Объем сбыта | K1: Выручка | L1: Себестоимость БУ | M1: РасходыНаПродажу | N1: Базисная ЕИ | O1: Формат_СС
E2: Сумма | O2: =SUM(O3:O2425) -> 2577873
A3: =VLOOKUP(D3,dict_name!L:M,2,FALSE) -> 214755 | B3: =VLOOKUP(A3,dict_name!B:D,3,FALSE) -> #N/A | C3: =VLOOKUP(E3,dict_prod!B:C,2,FALSE) -> m15041200 | D3: 13 ЭЛЕМЕНТ ООО | E3: 184500 | F3: 658722 | G3: Прокат латунный | H3: ЛИСТ ЛАТУНЬ 12*600*1500 ЛС59-1 ГПРХХ | J3: 0.706 | K3: 360162 | L3: 357478.44 | M3: 494.24 | N3: Т | O3: =ROUND(L3/1000,0) -> 357
A4: =VLOOKUP(D4,dict_name!L:M,2,FALSE) -> 214755 | B4: =VLOOKUP(A4,dict_name!B:D,3,FALSE) -> #N/A | C4: =VLOOKUP(E4,dict_prod!B:C,2,FALSE) -> m15041200 | D4: 13 ЭЛЕМЕНТ ООО | E4: 184500 | F4: 658725 | G4: Прокат латунный | H4: ЛИСТ ЛАТУНЬ 16*600*1500 ЛС59-1 ГПРХХ | J4: 1.517 | K4: 773670 | L4: 767905.4 | M4: 1061.68 | N4: Т | O4: =ROUND(L4/1000,0) -> 768
A5: =VLOOKUP(D5,dict_name!L:M,2,FALSE) -> 214755 | B5: =VLOOKUP(A5,dict_name!B:D,3,FALSE) -> #N/A | C5: =VLOOKUP(E5,dict_prod!B:C,2,FALSE) -> m15041300 | D5: 13 ЭЛЕМЕНТ ООО | E5: 188200 | F5: 657265 | G5: Прокат бронзовый | H5: ПРУТОК БРОНЗА 160 БРАЖ9-4 ПКРНХ | J5: 1.25 | K5: 718750 | L5: 714000 | M5: 986.32 | N5: Т | O5: =ROUND(L5/1000,0) -> 714
A6: =VLOOKUP(D6,dict_name!L:M,2,FALSE) -> 214755 | B6: =VLOOKUP(A6,dict_name!B:D,3,FALSE) -> #N/A | C6: =VLOOKUP(E6,dict_prod!B:C,2,FALSE) -> m15041300 | D6: 13 ЭЛЕМЕНТ ООО | E6: 188200 | F6: 658149 | G6: Прокат бронзовый | H6: ПРУТОК БРОНЗА 110 БРАМЦ9-2 ПКРНХ НД | J6: 0.962 | K6: 570466 | L6: 566810.4 | M6: 782.83 | N6: Т | O6: =ROUND(L6/1000,0) -> 567
A7: =VLOOKUP(D7,dict_name!L:M,2,FALSE) -> 212145 | B7: =VLOOKUP(A7,dict_name!B:D,3,FALSE) -> #N/A | C7: =VLOOKUP(E7,dict_prod!B:C,2,FALSE) -> m15041130 | D7: CGR TRANSILVANIA SRL | E7: 184400 | F7: 694324 | G7: Прокат медный | H7: ЛЕНТА МЕДЬ 1,2*39 CU-ETP Н065 EN 1652 | J7: 14.109 | K7: 10684346 | L7: 9618606.3 | M7: 20414.31 | N7: Т | O7: =ROUND(L7/1000,0) -> 9619
A8: =VLOOKUP(D8,dict_name!L:M,2,FALSE) -> 222292 | B8: =VLOOKUP(A8,dict_name!B:D,3,FALSE) -> #N/A | C8: =VLOOKUP(E8,dict_prod!B:C,2,FALSE) -> m15041130 | D8: MINMET TRADE DWC LLC | E8: 184400 | F8: 711150 | G8: Прокат медный | H8: ЛЕНТА МЕДЬ 1,8*151 CU-ETP R240 | J8: 6.692 | K8: 3675161.1 | L8: 3048094.5 | M8: 7022.03 | N8: Т | O8: =ROUND(L8/1000,0) -> 3048
A9: =VLOOKUP(D9,dict_name!L:M,2,FALSE) -> 222292 | B9: =VLOOKUP(A9,dict_name!B:D,3,FALSE) -> #N/A | C9: =VLOOKUP(E9,dict_prod!B:C,2,FALSE) -> m15041130 | D9: MINMET TRADE DWC LLC | E9: 184400 | F9: 711211 | G9: Прокат медный | H9: ЛЕНТА МЕДЬ 1,8*154 CU-ETP R240 | J9: 6.786 | K9: 3726784.7 | L9: 3090909.9 | M9: 7120.66 | N9: Т | O9: =ROUND(L9/1000,0) -> 3091
A10: =VLOOKUP(D10,dict_name!L:M,2,FALSE) -> 222292 | B10: =VLOOKUP(A10,dict_name!B:D,3,FALSE) -> #N/A | C10: =VLOOKUP(E10,dict_prod!B:C,2,FALSE) -> m15041130 | D10: MINMET TRADE DWC LLC | E10: 184400 | F10: 711212 | G10: Прокат медный | H10: ЛЕНТА МЕДЬ 1,8*157 CU-ETP R240 | J10: 6.8 | K10: 3734473.3 | L10: 3097286.7 | M10: 7135.36 | N10: Т | O10: =ROUND(L10/1000,0) -> 3097
A11: =VLOOKUP(D11,dict_name!L:M,2,FALSE) -> 68951 | B11: =VLOOKUP(A11,dict_name!B:D,3,FALSE) -> #N/A | C11: =VLOOKUP(E11,dict_prod!B:C,2,FALSE) -> m15098951 | D11: NOVA ЦИНК ТОО | E11: 252000 | F11: 694391 | G11: Шинная продукция | H11: ШИНА БЕЛШИНА 18.00R25 E4 BEL-183 | J11: 16 | K11: 1808000 | L11: 1808000 | M11: 3454.5 | N11: ШТ | O11: =ROUND(L11/1000,0) -> 1808
A12: =VLOOKUP(D12,dict_name!L:M,2,FALSE) -> 68951 | B12: =VLOOKUP(A12,dict_name!B:D,3,FALSE) -> #N/A | C12: =VLOOKUP(E12,dict_prod!B:C,2,FALSE) -> m15098951 | D12: NOVA ЦИНК ТОО | E12: 252000 | F12: 711824 | G12: Шинная продукция | H12: ШИНА БЕЛШИНА 24.00R35 E4 BEL-202 | J12: 12 | K12: 3576000 | L12: 3576000 | M12: 6832.5 | N12: ШТ | O12: =ROUND(L12/1000,0) -> 3576
A13: =VLOOKUP(D13,dict_name!L:M,2,FALSE) -> 11976 | B13: =VLOOKUP(A13,dict_name!B:D,3,FALSE) -> #N/A | C13: =VLOOKUP(E13,dict_prod!B:C,2,FALSE) -> m15041130 | D13: АВАР ПАО | E13: 184400 | F13: 707328 | G13: Прокат медный | H13: ЛЕНТА МЕДЬ 0,77*200 М1 ДПРПТ | J13: 3.156 | K13: 2032464 | L13: 1957351.2 | M13: 2789.09 | N13: Т | O13: =ROUND(L13/1000,0) -> 1957
A14: =VLOOKUP(D14,dict_name!L:M,2,FALSE) -> 11976 | B14: =VLOOKUP(A14,dict_name!B:D,3,FALSE) -> #N/A | C14: =VLOOKUP(E14,dict_prod!B:C,2,FALSE) -> m15041130 | D14: АВАР ПАО | E14: 184400 | F14: 711651 | G14: Прокат медный | H14: ЛЕНТА МЕДЬ 0,2*160 М1 ДПРПТ | J14: 1.029 | K14: 664760.69 | L14: 660852.39 | M14: 912.23 | N14: Т | O14: =ROUND(L14/1000,0) -> 661
A15: =VLOOKUP(D15,dict_name!L:M,2,FALSE) -> 11976 | B15: =VLOOKUP(A15,dict_name!B:D,3,FALSE) -> #N/A | C15: =VLOOKUP(E15,dict_prod!B:C,2,FALSE) -> m15041200 | D15: АВАР ПАО | E15: 184500 | F15: 701111 | G15: Прокат латунный | H15: ЛЕНТА ЛАТУНЬ 0,77*200 Л63 ДПРПП | J15: 7.012 | K15: 3512754.6 | L15: 3345869 | M15: 4820.45 | N15: Т | O15: =ROUND(L15/1000,0) -> 3346
A16: =VLOOKUP(D16,dict_name!L:M,2,FALSE) -> 11976 | B16: =VLOOKUP(A16,dict_name!B:D,3,FALSE) -> #N/A | C16: =VLOOKUP(E16,dict_prod!B:C,2,FALSE) -> m15041300 | D16: АВАР ПАО | E16: 188200 | F16: 710998 | G16: Прокат бронзовый | H16: ЛЕНТА БРОНЗА 0,15*200 БРОФ6,5-0,15 ДПРВТ | J16: 0.512 | K16: 665990 | L16: 664043.26 | M16: 913.92 | N16: Т | O16: =ROUND(L16/1000,0) -> 664
A17: =VLOOKUP(D17,dict_name!L:M,2,FALSE) -> 11976 | B17: =VLOOKUP(A17,dict_name!B:D,3,FALSE) -> #N/A | C17: =VLOOKUP(E17,dict_prod!B:C,2,FALSE) -> m15041300 | D17: АВАР ПАО | E17: 188200 | F17: 711213 | G17: Прокат бронзовый | H17: ЛЕНТА БРОНЗА 0,25*315 БРОФ6,5-0,15 ДПРПТ | J17: 0.479 | K17: 671020 | L17: 669198.66 | M17: 920.82 | N17: Т | O17: =ROUND(L17/1000,0) -> 669
A18: =VLOOKUP(D18,dict_name!L:M,2,FALSE) -> 196119 | B18: =VLOOKUP(A18,dict_name!B:D,3,FALSE) -> #N/A | C18: =VLOOKUP(E18,dict_prod!B:C,2,FALSE) -> m15041130 | D18: АВРОРА ЭЛЕКТРО ПК ООО | E18: 184400 | F18: 710349 | G18: Прокат медный | H18: ЛЕНТА МЕДЬ 0,5*500 М1 ДПРНМ | J18: 1.941 | K18: 1205361 | L18: 1197985.2 | M18: 1654.08 | N18: Т | O18: =ROUND(L18/1000,0) -> 1198
A19: =VLOOKUP(D19,dict_name!L:M,2,FALSE) -> 359 | B19: =VLOOKUP(A19,dict_name!B:D,3,FALSE) -> #N/A | C19: =VLOOKUP(E19,dict_prod!B:C,2,FALSE) -> m15041200 | D19: АВТОВАЗ АО | E19: 184500 | F19: 659358 | G19: Прокат латунный | H19: ТРУБА 67,8*53 ЛМЦАЖКС70-7-5-2-2-1 ПКР НД | J19: 5.098 | K19: 3216430.2 | L19: 3197057.8 | M19: 4413.82 | N19: Т | O19: =ROUND(L19/1000,0) -> 3197
... A2425: =VLOOKUP(D2425,dict_name!L:M,2,FALSE) -> 216712 | B2425: =VLOOKUP(A2425,dict_name!B:D,3,FALSE) -> #N/A | C2425: =VLOOKUP(E2425,dict_prod!B:C,2,FALSE) -> m15041300 | D2425: ЭТМ ООО | E2425: 188200 | F2425: 709689 | G2425: Прокат бронзовый | H2425: ПРУТОК БРОНЗА 175*700 БРАЖ9-4 ПКРНХ | J2425: 0.124 | K2425: 148998.4 | L2425: 148527.2 | M2425: 204.47 | N2425: Т | O2425: =ROUND(L2425/1000,0) -> 149

Sheet проверка_внешнего_ключа
A1: Код_sap | B1: ТекстКлиент | C1: sap | D1: assoi
C2: =SUM(C3:C263) -> 2577873 | D2: =SUM(D3:D263) -> 1841321
A3: 214755 | B3: 13 ЭЛЕМЕНТ ООО | C3: =SUMIFS(sap_11!O:O,sap_11!A:A,проверка_внешнего_ключа!A3) -> 2406 | D3: =SUMIFS(assoi!O:O,assoi!H:H,проверка_внешнего_ключа!A3) -> 0
A4: 212145 | B4: CGR TRANSILVANIA SRL | C4: =SUMIFS(sap_11!O:O,sap_11!A:A,проверка_внешнего_ключа!A4) -> 9619 | D4: =SUMIFS(assoi!O:O,assoi!H:H,проверка_внешнего_ключа!A4) -> 18478
A5: 222292 | B5: MINMET TRADE DWC LLC | C5: =SUMIFS(sap_11!O:O,sap_11!A:A,проверка_внешнего_ключа!A5) -> 9236 | D5: =SUMIFS(assoi!O:O,assoi!H:H,проверка_внешнего_ключа!A5) -> 0
A6: 68951 | B6: NOVA ЦИНК ТОО | C6: =SUMIFS(sap_11!O:O,sap_11!A:A,проверка_внешнего_ключа!A6) -> 5384 | D6: =SUMIFS(assoi!O:O,assoi!H:H,проверка_внешнего_ключа!A6) -> 1808
A7: 11976 | B7: АВАР ПАО | C7: =SUMIFS(sap_11!O:O,sap_11!A:A,проверка_внешнего_ключа!A7) -> 7297 | D7: =SUMIFS(assoi!O:O,assoi!H:H,проверка_внешнего_ключа!A7) -> 0
A8: 196119 | B8: АВРОРА ЭЛЕКТРО ПК ООО | C8: =SUMIFS(sap_11!O:O,sap_11!A:A,проверка_внешнего_ключа!A8) -> 1198 | D8: =SUMIFS(assoi!O:O,assoi!H:H,проверка_внешнего_ключа!A8) -> 0
A9: 359 | B9: АВТОВАЗ АО | C9: =SUMIFS(sap_11!O:O,sap_11!A:A,проверка_внешнего_ключа!A9) -> 17868 | D9: =SUMIFS(assoi!O:O,assoi!H:H,проверка_внешнего_ключа!A9) -> 17868
A10: 1790 | B10: АВТОДИЗЕЛЬ (ЯМЗ) ПАО | C10: =SUMIFS(sap_11!O:O,sap_11!A:A,проверка_внешнего_ключа!A10) -> 3129 | D10: =SUMIFS(assoi!O:O,assoi!H:H,проверка_внешнего_ключа!A10) -> 3129
A11: 74798 | B11: АВТОКОМПОНЕНТЫ - ГРУППА ГАЗ ООО | C11: =SUMIFS(sap_11!O:O,sap_11!A:A,проверка_внешнего_ключа!A11) -> 1233 | D11: =SUMIFS(assoi!O:O,assoi!H:H,проверка_внешнего_ключа!A11) -> 1233
A12: 219600 | B12: АВТОФОРМ ООО | C12: =SUMIFS(sap_11!O:O,sap_11!A:A,проверка_внешнего_ключа!A12) -> 167 | D12: =SUMIFS(assoi!O:O,assoi!H:H,проверка_внешнего_ключа!A12) -> 0
A13: 128692 | B13: АГРЕГАТ ПАО | C13: =SUMIFS(sap_11!O:O,sap_11!A:A,проверка_внешнего_ключа!A13) -> 2080 | D13: =SUMIFS(assoi!O:O,assoi!H:H,проверка_внешнего_ключа!A13) -> 0
A14: 178237 | B14: АДВЕРС ООО | C14: =SUMIFS(sap_11!O:O,sap_11!A:A,проверка_внешнего_ключа!A14) -> 1381 | D14: =SUMIFS(assoi!O:O,assoi!H:H,проверка_внешнего_ключа!A14) -> 0
... A263: 216712 | B263: ЭТМ ООО | C263: =SUMIFS(sap_11!O:O,sap_11!A:A,проверка_внешнего_ключа!A263) -> 467 | D263: =SUMIFS(assoi!O:O,assoi!H:H,проверка_внешнего_ключа!A263) -> 0

Sheet dict_name
A1: Контрагент КИС | B1: Код Контрагента КИС | C1: Контрагент АССОИ | D1: Код контрагента АССОИ | L1: ТекстКлиент | M1: Грузополучатель
L2: 13 ЭЛЕМЕНТ ООО | M2: 214755
A3: КУЗОЦМ АО | B3: 1258 | C3: ПАО "КУЗОЦМ" | D3: 2280 | L3: 13 ЭЛЕМЕНТ ООО | M3: 214755
A4: СТМ ООО | B4: 208535 | C4: СТМ ООО | D4: 12375 | L4: 13 ЭЛЕМЕНТ ООО | M4: 214755
A5: ЛИСТ СПБ ООО | B5: 69920 | C5: ООО "ЛИСТ СПб" | D5: 9950 | L5: 13 ЭЛЕМЕНТ ООО | M5: 214755
A6: НПЦ МЕТАЛЛУРГ ООО | B6: 66325 | C6: ООО "НПЦ Металлург" | D6: 10722 | L6: 13 ЭЛЕМЕНТ ООО | M6: 214755
A7: АЛЬМЕТ ООО | B7: 126128 | C7: ООО "АЛЬМЕТ" | D7: 10723 | L7: 13 ЭЛЕМЕНТ ООО | M7: 214755
A8: СВЕРДЛОВЭЛЕКТРО ООО | B8: 20784 | C8: ООО "СВЕРДЛОВЭЛЕКТРО" | D8: 10837 | L8: 13 ЭЛЕМЕНТ ООО | M8: 214755
A9: СПИРАЛЬ ООО | B9: 124818 | C9: ООО "СПИРАЛЬ" | D9: 10842 | L9: 13 ЭЛЕМЕНТ ООО | M9: 214755
A10: УРОМГАЗ-ИРБИТ ООО | B10: 125683 | C10: ООО "Уромгаз-Ирбит" | D10: 10845 | L10: 13 ЭЛЕМЕНТ ООО | M10: 214755
A11: ПОЗИС АО | B11: 135819 | C11: АО "ПОЗИС" | D11: 10848 | L11: 13 ЭЛЕМЕНТ ООО | M11: 214755
A12: ДКС АО | B12: 205357 | C12: АО "ДКС" | D12: 10856 | L12: 13 ЭЛЕМЕНТ ООО | M12: 214755
A13: НПК МЕТАПРОМ ООО | B13: 208503 | C13: НПК МЕТАПРОМ ООО | D13: 10857 | L13: 13 ЭЛЕМЕНТ ООО | M13: 214755
A14: МЕЛЬХИОР ООО | B14: 208504 | C14: МЕЛЬХИОР ООО | D14: 10858 | L14: 13 ЭЛЕМЕНТ ООО | M14: 214755
... A199: ШСУ ООО | B199: 80605 | C199: ООО "Шахтостроительное управление" | D199: 5325 | L199: MINMET TRADE DWC LLC | M199: 222292
L200: MINMET TRADE DWC LLC | M200: 222292
L201: MINMET TRADE DWC LLC | M201: 222292
L202: MINMET TRADE DWC LLC | M202: 222292
L203: MINMET TRADE DWC LLC | M203: 222292
L204: MINMET TRADE DWC LLC | M204: 222292
L205: MINMET TRADE DWC LLC | M205: 222292
L206: MINMET TRADE DWC LLC | M206: 222292
L207: MINMET TRADE DWC LLC | M207: 222292
L208: MINMET TRADE DWC LLC | M208: 222292
L209: MINMET TRADE DWC LLC | M209: 222292
L210: MINMET TRADE DWC LLC | M210: 222292
L211: MINMET TRADE DWC LLC | M211: 222292
... L37440: ЭТМ ООО | M37440: 216712

Sheet dict_prod
A1: Консолидирующая | P1: Консолидирующая (старая)
A2: Материал | B2: Группа материалов | C2: Код АССОИ | E2: Группа материалов | F2: Код АССОИ | G2: КА АССОИ (прочие) | I2: Наименование контрагента КИС | J2: Код контрагента АССОИ | P2: Материал | Q2: Группа материалов | R2: Код АССОИ
A3: 143048 | C3: m15041150 | E3: 184400 | F3: m15041130 | G3: 2562 | I3: СУМЗ ПАО | J3: 449 | P3: 143048 | R3: m15041150
A4: 641761 | C4: m15085100 | E4: 184200 | F4: m15041500 | G4: 2562 | I4: СВЯТОГОР АО | J4: 353 | P4: 641761 | R4: m15085100
A5: 641748 | C5: m15085100 | E5: 184500 | F5: m15041200 | G5: 2562 | I5: ШААЗ АО | J5: 362 | P5: 641748 | R5: m15085100
A6: 125269 | B6: 71000 | C6: =IFERROR(VLOOKUP(VALUE(B6),E:F,2,FALSE),"") | E6: 180000 | F6: m15041130 | G6: 2562 | I6: КЗОЦМ АО | J6: 468 | P6: 125269 | Q6: 71000 | R6: =IFERROR(VLOOKUP(VALUE(Q6),T:U,2,FALSE),"")
A7: 125269 | B7: 71240 | C7: =IFERROR(VLOOKUP(VALUE(B7),E:F,2,FALSE),"") | E7: 188200 | F7: m15041300 | G7: 2562 | I7: НАДЕЖДИНСКИЙ МЕТ.ЗАВОД ПАО | J7: 354 | P7: 125269 | Q7: 71240 | R7: =IFERROR(VLOOKUP(VALUE(Q7),T:U,2,FALSE),"")
A8: 562825 | B8: 71240 | C8: =IFERROR(VLOOKUP(VALUE(B8),E:F,2,FALSE),"") | E8: 173300 | F8: m15032100 | G8: 2562 | I8: ЧЦЗ АО | J8: 1108 | P8: 562825 | Q8: 71240 | R8: =IFERROR(VLOOKUP(VALUE(Q8),T:U,2,FALSE),"")
A9: 655582 | B9: 184400 | C9: =IFERROR(VLOOKUP(VALUE(B9),E:F,2,FALSE),"") -> m15041130 | E9: 351000 | F9: m150551231 | G9: 3582 | I9: ОРЕНБУРГСКИЙ РАДИАТОР ООО | J9: 471 | P9: 655582 | Q9: 184400 | R9: =IFERROR(VLOOKUP(VALUE(Q9),T:U,2,FALSE),"")
A10: 670758 | B10: 184500 | C10: =IFERROR(VLOOKUP(VALUE(B10),E:F,2,FALSE),"") -> m15041200 | E10: 350000 | F10: m15055024 | G10: 3582 | I10: МИХЕЛЬ ДАСТИН ООО | J10: 2809 | P10: 670758 | Q10: 184500 | R10: =IFERROR(VLOOKUP(VALUE(Q10),T:U,2,FALSE),"")
A11: 670760 | B11: 184500 | C11: =IFERROR(VLOOKUP(VALUE(B11),E:F,2,FALSE),"") -> m15041200 | E11: 141580 | F11: m15084752 | G11: 3582 | I11: УЧАЛИНСКИЙ ГОК АО | J11: 472 | P11: 670760 | Q11: 184500 | R11: =IFERROR(VLOOKUP(VALUE(Q11),T:U,2,FALSE),"")
A12: 670772 | B12: 184500 | C12: =IFERROR(VLOOKUP(VALUE(B12),E:F,2,FALSE),"") -> m15041200 | E12: 317632 | F12: =F11 -> m15084752 | G12: 3582 | I12: РЗ ОЦМ ПАО | J12: 415 | P12: 670772 | Q12: 184500 | R12: =IFERROR(VLOOKUP(VALUE(Q12),T:U,2,FALSE),"")
A13: 670796 | B13: 184500 | C13: =IFERROR(VLOOKUP(VALUE(B13),E:F,2,FALSE),"") -> m15041200 | E13: 314110 | F13: m15085520 | I13: УГМК-СТАЛЬ ООО | J13: 1047 | P13: 670796 | Q13: 184500 | R13: =IFERROR(VLOOKUP(VALUE(Q13),T:U,2,FALSE),"")
A14: 673677 | B14: 184400 | C14: =IFERROR(VLOOKUP(VALUE(B14),E:F,2,FALSE),"") -> m15041130 | E14: 460000 | F14: m150846029 | I14: БАШМЕДЬ ООО | J14: 1062 | P14: 673677 | Q14: 184400 | R14: =IFERROR(VLOOKUP(VALUE(Q14),T:U,2,FALSE),"")
A15: 673678 | B15: 184400 | C15: =IFERROR(VLOOKUP(VALUE(B15),E:F,2,FALSE),"") -> m15041130 | E15: 260000 | F15: m15081404 | I15: ГАЙСКИЙ ГОК ПАО | J15: 467 | P15: 673678 | Q15: 184400 | R15: =IFERROR(VLOOKUP(VALUE(Q15),T:U,2,FALSE),"")
A16: 673680 | B16: 184400 | C16: =IFERROR(VLOOKUP(VALUE(B16),E:F,2,FALSE),"") -> m15041130 | E16: 150000 | F16: m15063411 | I16: СИБКАБЕЛЬ АО | J16: 693 | P16: 673680 | Q16: 184400 | R16: =IFERROR(VLOOKUP(VALUE(Q16),T:U,2,FALSE),"")
A17: 650618 | B17: 184500 | C17: =IFERROR(VLOOKUP(VALUE(B17),E:F,2,FALSE),"") -> m15041200 | E17: 252000 | F17: m15098951 | I17: УРАЛЭЛЕКТРОМЕДЬ АО | J17: 352 | P17: 650618 | Q17: 184500 | R17: =IFERROR(VLOOKUP(VALUE(Q17),T:U,2,FALSE),"")
A18: 671362 | B18: 184400 | C18: =IFERROR(VLOOKUP(VALUE(B18),E:F,2,FALSE),"") -> m15041130 | E18: 40086 | F18: m150411201 | I18: СУХОЛОЖСКОЕ ЛИТЬЕ АО | J18: 857 | P18: 671362 | Q18: 184400 | R18: =IFERROR(VLOOKUP(VALUE(Q18),T:U,2,FALSE),"")
A19: 670798 | B19: 184400 | C19: =IFERROR(VLOOKUP(VALUE(B19),E:F,2,FALSE),"") -> m15041130 | E19: 143048 | F19: m15041150 | G19: 3295 | I19: УК КУЗБАССРАЗРЕЗУГОЛЬ АО | J19: 1067 | P19: 670798 | Q19: 184400 | R19: =IFERROR(VLOOKUP(VALUE(Q19),T:U,2,FALSE),"")
A20: 672847 | B20: 184400 | C20: =IFERROR(VLOOKUP(VALUE(B20),E:F,2,FALSE),"") -> m15041130 | E20: 641761 | F20: m15041150 | G20: 2371 | I20: АВТОДИЗЕЛЬ (ЯМЗ) ПАО | J20: 7223 | P20: 672847 | Q20: 184400 | R20: =IFERROR(VLOOKUP(VALUE(Q20),T:U,2,FALSE),"")
A21: 257514 | B21: 252000 | C21: =IFERROR(VLOOKUP(VALUE(B21),E:F,2,FALSE),"") -> m15098951 | E21: 641748 | F21: m15041150 | G21: 2371 | I21: ТЭМЗ АО | J21: 10875 | P21: 257514 | Q21: 252000 | R21: =IFERROR(VLOOKUP(VALUE(Q21),T:U,2,FALSE),"")
A22: 336035 | B22: 252000 | C22: =IFERROR(VLOOKUP(VALUE(B22),E:F,2,FALSE),"") -> m15098951 | E22: 173323 | F22: m15031600 | I22: КАЛУЖСКИЙ ТУРБИННЫЙ ЗАВОД ПАО | J22: 9814 | P22: 336035 | Q22: 252000 | R22: =IFERROR(VLOOKUP(VALUE(Q22),T:U,2,FALSE),"")
A23: 440585 | B23: 252000 | C23: =IFERROR(VLOOKUP(VALUE(B23),E:F,2,FALSE),"") -> m15098951 | I23: АЗ УРАЛ АО | J23: 3919 | P23: 440585 | Q23: 252000 | R23: =IFERROR(VLOOKUP(VALUE(Q23),T:U,2,FALSE),"")
A24: 518019 | B24: 252000 | C24: =IFERROR(VLOOKUP(VALUE(B24),E:F,2,FALSE),"") -> m15098951 | I24: СВЕРДЛ.ЗАВОД ТРАНСФОРМАТ.ТОКА | J24: 12395 | P24: 518019 | Q24: 252000 | R24: =IFERROR(VLOOKUP(VALUE(Q24),T:U,2,FALSE),"")
A25: 528261 | B25: 252000 | C25: =IFERROR(VLOOKUP(VALUE(B25),E:F,2,FALSE),"") -> m15098951 | P25: 528261 | Q25: 252000 | R25: =IFERROR(VLOOKUP(VALUE(Q25),T:U,2,FALSE),"")
A26: 591987 | B26: 252000 | C26: =IFERROR(VLOOKUP(VALUE(B26),E:F,2,FALSE),"") -> m15098951 | P26: 591987 | Q26: 252000 | R26: =IFERROR(VLOOKUP(VALUE(Q26),T:U,2,FALSE),"")
A27: 594714 | B27: 252000 | C27: =IFERROR(VLOOKUP(VALUE(B27),E:F,2,FALSE),"") -> m15098951 | P27: 594714 | Q27: 252000 | R27: =IFERROR(VLOOKUP(VALUE(Q27),T:U,2,FALSE),"")
A28: 657068 | B28: 184500 | C28: =IFERROR(VLOOKUP(VALUE(B28),E:F,2,FALSE),"") -> m15041200 | P28: 657068 | Q28: 184500 | R28: =IFERROR(VLOOKUP(VALUE(Q28),T:U,2,FALSE),"")
A29: 658172 | B29: 184500 | C29: =IFERROR(VLOOKUP(VALUE(B29),E:F,2,FALSE),"") -> m15041200 | P29: 658172 | Q29: 184500 | R29: =IFERROR(VLOOKUP(VALUE(Q29),T:U,2,FALSE),"")
A30: 659358 | B30: 184500 | C30: =IFERROR(VLOOKUP(VALUE(B30),E:F,2,FALSE),"") -> m15041200 | P30: 659358 | Q30: 184500 | R30: =IFERROR(VLOOKUP(VALUE(Q30),T:U,2,FALSE),"")
A31: 659897 | B31: 184500 | C31: =IFERROR(VLOOKUP(VALUE(B31),E:F,2,FALSE),"") -> m15041200 | P31: 659897 | Q31: 184500 | R31: =IFERROR(VLOOKUP(VALUE(Q31),T:U,2,FALSE),"")
A32: 660242 | B32: 184500 | C32: =IFERROR(VLOOKUP(VALUE(B32),E:F,2,FALSE),"") -> m15041200 | P32: 660242 | Q32: 184500 | R32: =IFERROR(VLOOKUP(VALUE(Q32),T:U,2,FALSE),"")
A33: 641695 | B33: 270000 | C33: =IFERROR(VLOOKUP(VALUE(B33),E:F,2,FALSE),"") | P33: 641695 | Q33: 270000 | R33: =IFERROR(VLOOKUP(VALUE(Q33),T:U,2,FALSE),"")
A34: 637563 | B34: 313000 | C34: =IFERROR(VLOOKUP(VALUE(B34),E:F,2,FALSE),"") | P34: 637563 | Q34: 313000 | R34: =IFERROR(VLOOKUP(VALUE(Q34),T:U,2,FALSE),"")
A35: 637661 | B35: 313000 | C35: =IFERROR(VLOOKUP(VALUE(B35),E:F,2,FALSE),"") | P35: 637661 | Q35: 313000 | R35: =IFERROR(VLOOKUP(VALUE(Q35),T:U,2,FALSE),"")
A36: 637678 | B36: 313000 | C36: =IFERROR(VLOOKUP(VALUE(B36),E:F,2,FALSE),"") | P36: 637678 | Q36: 313000 | R36: =IFERROR(VLOOKUP(VALUE(Q36),T:U,2,FALSE),"")
... A4808: 654273 | B4808: 184500 | C4808: =IFERROR(VLOOKUP(VALUE(B4808),E:F,2,FALSE),"") -> m15041200 | P4808: 654273 | Q4808: 184500 | R4808: =IFERROR(VLOOKUP(VALUE(Q4808),T:U,2,FALSE),"")
A4809: 697880 | B4809: 184400 | C4809: =IFERROR(VLOOKUP(VALUE(B4809),E:F,2,FALSE),"") -> m15041130 | R4809: =IFERROR(VLOOKUP(VALUE(Q4809),T:U,2,FALSE),"")
A4810: 697971 | B4810: 184400 | C4810: =IFERROR(VLOOKUP(VALUE(B4810),E:F,2,FALSE),"") -> m15041130 | R4810: =IFERROR(VLOOKUP(VALUE(Q4810),T:U,2,FALSE),"")
A4811: 697731 | B4811: 184400 | C4811: =IFERROR(VLOOKUP(VALUE(B4811),E:F,2,FALSE),"") -> m15041130 | R4811: =IFERROR(VLOOKUP(VALUE(Q4811),T:U,2,FALSE),"")
...
